Workbook

Sheet METADADOS
A1: ANO | B1: Valor do ano
A2: MES | B2: Valor do mês
A3: HEL | B3: movimento de helicópteros | C3: TATIC FLOW e BIMTRA (somente dados de SBBR)
A4: RPC | B4: Renda Per Capita | C4: https://anuario.ipe.df.gov.br/home
A5: POP | B5: População | C5: https://anuario.ipe.df.gov.br/home
A6: FROTA | B6: Frota | C6: https://app.powerbi.com/view?r=eyJrIjoiMGQ2MjdiMWYtNzQxZS00Mzk2LWE0NmEtMzFiMTNmNzI1OTk3IiwidCI6ImI1NzQ4ZjZlLWI0YTQtNGIyYi1hYjJhLWVmOTUyMjM2ODM2NiIsImMiOjR9
A7: HELIPT | B7: Helipontos | C7: https://www.gov.br/anac/pt-br/assuntos/regulados/aeroportos-e-aerodromos/lista-de-aerodromos-civis-cadastrados
A8: QAV | B8: Preço do QAV | C8: https://www.gov.br/anp/pt-br/assuntos/precos-e-defesa-da-concorrencia/precos/precos-de-produtores-e-importadores-de-derivados-de-petroleo-e-biodiesel
A9: QAVREF | B9: Preço do QAV corrigido pelo IPCA para o mês de ref (mar/26)
A10: PAND | B10: Dummy Pandemia | C10: A partir de mar/20 = 1

Sheet AD
A1: COD ICAO | B1: MUNICIPIO | C1: UF | D1: TIPO
A2: SBBR | B2: BRASÍLIA | C2: DF | D2: AD PUB
A3: SJXU | B3: BRASÍLIA | C3: DF | D3: AD PRIV
A4: SINA | B4: BRASÍLIA | C4: DF | D4: AD PRIV
A5: SSWB | B5: BRASÍLIA | C5: DF | D5: AD PRIV
A6: SDCB | B6: BRASÍLIA | C6: DF | D6: AD PRIV
A7: SSGP | B7: BRASÍLIA | C7: DF | D7: AD PRIV
A8: SWXU | B8: BRASÍLIA | C8: DF | D8: AD PRIV
A9: SIQE | B9: BRASÍLIA | C9: DF | D9: AD PRIV
A10: SWDF | B10: BRASÍLIA | C10: DF | D10: HELIPT
A11: SDHH | B11: BRASÍLIA | C11: DF | D11: HELIPT
A12: SDZA | B12: BRASÍLIA | C12: DF | D12: HELIPT
... A21: SI4J | B21: BRASÍLIA | C21: DF | D21: HELIPT

Sheet DADOS
A1: ANO | B1: MES | C1: DATA | D1: HEL | E1: RPC | F1: POP | G1: FROTA | H1: HELIPT | I1: QAV | J1: QAVREF | K1: PAND
A2: 2019 | B2: 1 | C2: =DATE(DADOS!$A2,DADOS!$B2,1) -> 1/1/2019 | D2: 589 | E2: 2047.86 | F2: 3015000 | H2: 6 | K2: 0
A3: 2019 | B3: 2 | C3: =DATE(DADOS!$A3,DADOS!$B3,1) -> 2/1/2019 | D3: 601 | E3: 2047.86 | F3: 3015000 | H3: 6 | K3: 0
A4: 2019 | B4: 3 | C4: =DATE(DADOS!$A4,DADOS!$B4,1) -> 3/1/2019 | D4: 579 | E4: 2047.86 | F4: 3015000 | H4: 6 | K4: 0
A5: 2019 | B5: 4 | C5: =DATE(DADOS!$A5,DADOS!$B5,1) -> 4/1/2019 | D5: 614 | E5: 2047.86 | F5: 3015000 | H5: 6 | K5: 0
A6: 2019 | B6: 5 | C6: =DATE(DADOS!$A6,DADOS!$B6,1) -> 5/1/2019 | D6: 670 | E6: 2047.86 | F6: 3015000 | H6: 6 | K6: 0
A7: 2019 | B7: 6 | C7: =DATE(DADOS!$A7,DADOS!$B7,1) -> 6/1/2019 | D7: 636 | E7: 2047.86 | F7: 3015000 | H7: 6 | K7: 0
A8: 2019 | B8: 7 | C8: =DATE(DADOS!$A8,DADOS!$B8,1) -> 7/1/2019 | D8: 763 | E8: 2047.86 | F8: 3015000 | H8: 6 | K8: 0
A9: 2019 | B9: 8 | C9: =DATE(DADOS!$A9,DADOS!$B9,1) -> 8/1/2019 | D9: 805 | E9: 2047.86 | F9: 3015000 | H9: 6 | K9: 0
A10: 2019 | B10: 9 | C10: =DATE(DADOS!$A10,DADOS!$B10,1) -> 9/1/2019 | D10: 612 | E10: 2047.86 | F10: 3015000 | H10: 6 | K10: 0
A11: 2019 | B11: 10 | C11: =DATE(DADOS!$A11,DADOS!$B11,1) -> 10/1/2019 | D11: 679 | E11: 2047.86 | F11: 3015000 | H11: 7 | K11: 0
A12: 2019 | B12: 11 | C12: =DATE(DADOS!$A12,DADOS!$B12,1) -> 11/1/2019 | D12: 624 | E12: 2047.86 | F12: 3015000 | H12: 7 | K12: 0
A13: 2019 | B13: 12 | C13: =DATE(DADOS!$A13,DADOS!$B13,1) -> 12/1/2019 | D13: 700 | E13: 2047.86 | F13: 3015000 | H13: 7 | K13: 0
A14: 2020 | B14: 1 | C14: =DATE(DADOS!$A14,DADOS!$B14,1) -> 1/1/2020 | D14: 597 | F14: 3052546 | H14: 7 | K14: 0
A15: 2020 | B15: 2 | C15: =DATE(DADOS!$A15,DADOS!$B15,1) -> 2/1/2020 | D15: 526 | F15: 3052546 | H15: 7 | K15: 0
A16: 2020 | B16: 3 | C16: =DATE(DADOS!$A16,DADOS!$B16,1) -> 3/1/2020 | D16: 563 | F16: 3052546 | H16: 7 | K16: 0
A17: 2020 | B17: 4 | C17: =DATE(DADOS!$A17,DADOS!$B17,1) -> 4/1/2020 | D17: 340 | F17: 3052546 | H17: 7 | K17: 1
A18: 2020 | B18: 5 | C18: =DATE(DADOS!$A18,DADOS!$B18,1) -> 5/1/2020 | D18: 448 | F18: 3052546 | H18: 7 | K18: 1
A19: 2020 | B19: 6 | C19: =DATE(DADOS!$A19,DADOS!$B19,1) -> 6/1/2020 | D19: 486 | F19: 3052546 | H19: 7 | K19: 1
A20: 2020 | B20: 7 | C20: =DATE(DADOS!$A20,DADOS!$B20,1) -> 7/1/2020 | D20: 517 | F20: 3052546 | H20: 7 | K20: 1
A21: 2020 | B21: 8 | C21: =DATE(DADOS!$A21,DADOS!$B21,1) -> 8/1/2020 | D21: 402 | F21: 3052546 | H21: 7 | K21: 1
A22: 2020 | B22: 9 | C22: =DATE(DADOS!$A22,DADOS!$B22,1) -> 9/1/2020 | D22: 406 | F22: 3052546 | H22: 7 | K22: 1
A23: 2020 | B23: 10 | C23: =DATE(DADOS!$A23,DADOS!$B23,1) -> 10/1/2020 | D23: 456 | F23: 3052546 | H23: 7 | K23: 1
A24: 2020 | B24: 11 | C24: =DATE(DADOS!$A24,DADOS!$B24,1) -> 11/1/2020 | D24: 417 | F24: 3052546 | H24: 8 | K24: 1
A25: 2020 | B25: 12 | C25: =DATE(DADOS!$A25,DADOS!$B25,1) -> 12/1/2020 | D25: 490 | F25: 3052546 | H25: 8 | K25: 1
A26: 2021 | B26: 1 | C26: =DATE(DADOS!$A26,DADOS!$B26,1) -> 1/1/2021 | D26: 401 | E26: 2320.55 | F26: 3091667 | H26: 8 | K26: 1
A27: 2021 | B27: 2 | C27: =DATE(DADOS!$A27,DADOS!$B27,1) -> 2/1/2021 | D27: 422 | E27: 2320.55 | F27: 3091667 | H27: 8 | K27: 1
A28: 2021 | B28: 3 | C28: =DATE(DADOS!$A28,DADOS!$B28,1) -> 3/1/2021 | D28: 485 | E28: 2320.55 | F28: 3091667 | H28: 8 | K28: 1
A29: 2021 | B29: 4 | C29: =DATE(DADOS!$A29,DADOS!$B29,1) -> 4/1/2021 | D29: 432 | E29: 2320.55 | F29: 3091667 | H29: 8 | K29: 1
A30: 2021 | B30: 5 | C30: =DATE(DADOS!$A30,DADOS!$B30,1) -> 5/1/2021 | D30: 412 | E30: 2320.55 | F30: 3091667 | H30: 8 | K30: 1
A31: 2021 | B31: 6 | C31: =DATE(DADOS!$A31,DADOS!$B31,1) -> 6/1/2021 | D31: 549 | E31: 2320.55 | F31: 3091667 | H31: 8 | K31: 1
A32: 2021 | B32: 7 | C32: =DATE(DADOS!$A32,DADOS!$B32,1) -> 7/1/2021 | D32: 527 | E32: 2320.55 | F32: 3091667 | H32: 8 | K32: 1
A33: 2021 | B33: 8 | C33: =DATE(DADOS!$A33,DADOS!$B33,1) -> 8/1/2021 | D33: 631 | E33: 2320.55 | F33: 3091667 | H33: 8 | K33: 1
A34: 2021 | B34: 9 | C34: =DATE(DADOS!$A34,DADOS!$B34,1) -> 9/1/2021 | D34: 599 | E34: 2320.55 | F34: 3091667 | H34: 8 | K34: 1
A35: 2021 | B35: 10 | C35: =DATE(DADOS!$A35,DADOS!$B35,1) -> 10/1/2021 | D35: 557 | E35: 2320.55 | F35: 3091667 | H35: 9 | K35: 1
A36: 2021 | B36: 11 | C36: =DATE(DADOS!$A36,DADOS!$B36,1) -> 11/1/2021 | D36: 613 | E36: 2320.55 | F36: 3091667 | H36: 9 | K36: 1
A37: 2021 | B37: 12 | C37: =DATE(DADOS!$A37,DADOS!$B37,1) -> 12/1/2021 | D37: 733 | E37: 2320.55 | F37: 3091667 | H37: 9 | K37: 1
A38: 2022 | B38: 1 | C38: =DATE(DADOS!$A38,DADOS!$B38,1) -> 1/1/2022 | D38: 390 | F38: 3130014 | H38: 9 | K38: 1
A39: 2022 | B39: 2 | C39: =DATE(DADOS!$A39,DADOS!$B39,1) -> 2/1/2022 | D39: 481 | F39: 3130014 | H39: 9 | K39: 1
A40: 2022 | B40: 3 | C40: =DATE(DADOS!$A40,DADOS!$B40,1) -> 3/1/2022 | D40: 552 | F40: 3130014 | H40: 10 | I40: 4.1585 | J40: 4.9680865 | K40: 1
...

Sheet CORRELAÇÃO
B1: DATA | C1: HEL | D1: RPC | E1: POP | F1: FROTA | G1: HELIPT | H1: QAV | I1: PAND
A2: DATA | B2: 1
A3: HEL | B3: -0.040536515 | C3: 1
A4: RPC | B4: 0.98200809 | C4: -0.50420655 | D4: 1
A5: POP | B5: 0.9860511 | C5: -0.10708061 | D5: 0.9923543 | E5: 1
A6: FROTA | B6: #DIV/0! | C6: #DIV/0! | D6: #DIV/0! | E6: #DIV/0! | F6: 1
A7: HELIPT | B7: 0.96095582 | C7: 0.010908193 | D7: 0.97156449 | E7: 0.97344418 | F7: #DIV/0! | G7: 1
A8: QAV | B8: -0.57434741 | C8: 0.18662104 | D8: #DIV/0! | E8: -0.32362644 | F8: #DIV/0! | G8: -0.23594758 | H8: 1
A9: PAND | B9: 0.65438026 | C9: -0.34736656 | D9: 0.87344854 | E9: 0.69334604 | F9: #DIV/0! | G9: 0.6609322 | H9: #DIV/0! | I9: 1

Sheet MODELO 1
A1: ANO | B1: MES | C1: DATA | D1: HEL
A2: 2019 | B2: 1 | C2: =DATE('MODELO 1'!$A2,'MODELO 1'!$B2,1) -> 1/1/2019 | D2: 589 | F2: SUMMARY OUTPUT
A3: 2019 | B3: 2 | C3: =DATE('MODELO 1'!$A3,'MODELO 1'!$B3,1) -> 2/1/2019 | D3: 601
A4: 2019 | B4: 3 | C4: =DATE('MODELO 1'!$A4,'MODELO 1'!$B4,1) -> 3/1/2019 | D4: 579 | F4: Regression Statistics
A5: 2019 | B5: 4 | C5: =DATE('MODELO 1'!$A5,'MODELO 1'!$B5,1) -> 4/1/2019 | D5: 614 | F5: Multiple R | G5: 0.040536515
A6: 2019 | B6: 5 | C6: =DATE('MODELO 1'!$A6,'MODELO 1'!$B6,1) -> 5/1/2019 | D6: 670 | F6: R Square | G6: 0.001643209
A7: 2019 | B7: 6 | C7: =DATE('MODELO 1'!$A7,'MODELO 1'!$B7,1) -> 6/1/2019 | D7: 636 | F7: Adjusted R Square | G7: -0.010102165
A8: 2019 | B8: 7 | C8: =DATE('MODELO 1'!$A8,'MODELO 1'!$B8,1) -> 7/1/2019 | D8: 763 | F8: Standard Error | G8: 106.00769
A9: 2019 | B9: 8 | C9: =DATE('MODELO 1'!$A9,'MODELO 1'!$B9,1) -> 8/1/2019 | D9: 805 | F9: Observations | G9: 87
A10: 2019 | B10: 9 | C10: =DATE('MODELO 1'!$A10,'MODELO 1'!$B10,1) -> 9/1/2019 | D10: 612
A11: 2019 | B11: 10 | C11: =DATE('MODELO 1'!$A11,'MODELO 1'!$B11,1) -> 10/1/2019 | D11: 679 | F11: ANOVA
A12: 2019 | B12: 11 | C12: =DATE('MODELO 1'!$A12,'MODELO 1'!$B12,1) -> 11/1/2019 | D12: 624 | G12: df | H12: SS | I12: MS | J12: F | K12: Significance F
A13: 2019 | B13: 12 | C13: =DATE('MODELO 1'!$A13,'MODELO 1'!$B13,1) -> 12/1/2019 | D13: 700 | F13: Regression | G13: 1 | H13: 1572.1743 | I13: 1572.1743 | J13: 0.13990266 | K13: 0.70930921
A14: 2020 | B14: 1 | C14: =DATE('MODELO 1'!$A14,'MODELO 1'!$B14,1) -> 1/1/2020 | D14: 597 | F14: Residual | G14: 85 | H14: 955198.54 | I14: 11237.63
A15: 2020 | B15: 2 | C15: =DATE('MODELO 1'!$A15,'MODELO 1'!$B15,1) -> 2/1/2020 | D15: 526 | F15: Total | G15: 86 | H15: 956770.71
A16: 2020 | B16: 3 | C16: =DATE('MODELO 1'!$A16,'MODELO 1'!$B16,1) -> 3/1/2020 | D16: 563
A17: 2020 | B17: 4 | C17: =DATE('MODELO 1'!$A17,'MODELO 1'!$B17,1) -> 4/1/2020 | D17: 340 | G17: Coefficients | H17: Standard Error | I17: t Stat | J17: P-value | K17: Lower 95% | L17: Upper 95% | M17: Lower 95,0% | N17: Upper 95,0%
A18: 2020 | B18: 5 | C18: =DATE('MODELO 1'!$A18,'MODELO 1'!$B18,1) -> 5/1/2020 | D18: 448 | F18: Intercept | G18: 806.36844 | H18: 665.7492 | I18: 1.2112195 | J18: 0.22916801 | K18: -517.31933 | L18: 2130.0562 | M18: -517.31933 | N18: 2130.0562
A19: 2020 | B19: 6 | C19: =DATE('MODELO 1'!$A19,'MODELO 1'!$B19,1) -> 6/1/2020 | D19: 486 | F19: DATA | G19: -0.005560731 | H19: 0.014866848 | I19: -0.37403564 | J19: 0.70930921 | K19: -0.035120008 | L19: 0.023998546 | M19: -0.035120008 | N19: 0.023998546
A20: 2020 | B20: 7 | C20: =DATE('MODELO 1'!$A20,'MODELO 1'!$B20,1) -> 7/1/2020 | D20: 517
A21: 2020 | B21: 8 | C21: =DATE('MODELO 1'!$A21,'MODELO 1'!$B21,1) -> 8/1/2020 | D21: 402
A22: 2020 | B22: 9 | C22: =DATE('MODELO 1'!$A22,'MODELO 1'!$B22,1) -> 9/1/2020 | D22: 406
A23: 2020 | B23: 10 | C23: =DATE('MODELO 1'!$A23,'MODELO 1'!$B23,1) -> 10/1/2020 | D23: 456 | F23: RESIDUAL OUTPUT | K23: PROBABILITY OUTPUT
A24: 2020 | B24: 11 | C24: =DATE('MODELO 1'!$A24,'MODELO 1'!$B24,1) -> 11/1/2020 | D24: 417
A25: 2020 | B25: 12 | C25: =DATE('MODELO 1'!$A25,'MODELO 1'!$B25,1) -> 12/1/2020 | D25: 490 | F25: Observation | G25: Predicted HEL | H25: Residuals | I25: Standard Residuals | K25: Percentile | L25: HEL
A26: 2021 | B26: 1 | C26: =DATE('MODELO 1'!$A26,'MODELO 1'!$B26,1) -> 1/1/2021 | D26: 401 | F26: 1 | G26: 564.66571 | H26: 24.334289 | I26: 0.23089848 | K26: 0.57471264 | L26: 340
A27: 2021 | B27: 2 | C27: =DATE('MODELO 1'!$A27,'MODELO 1'!$B27,1) -> 2/1/2021 | D27: 422 | F27: 2 | G27: 564.49333 | H27: 36.506672 | I27: 0.34639742 | K27: 1.7241379 | L27: 368
A28: 2021 | B28: 3 | C28: =DATE('MODELO 1'!$A28,'MODELO 1'!$B28,1) -> 3/1/2021 | D28: 485 | F28: 3 | G28: 564.33763 | H28: 14.662372 | I28: 0.13912547 | K28: 2.8735632 | L28: 386
A29: 2021 | B29: 4 | C29: =DATE('MODELO 1'!$A29,'MODELO 1'!$B29,1) -> 4/1/2021 | D29: 432 | F29: 4 | G29: 564.16525 | H29: 49.834755 | I29: 0.47286234 | K29: 4.0229885 | L29: 390
A30: 2021 | B30: 5 | C30: =DATE('MODELO 1'!$A30,'MODELO 1'!$B30,1) -> 5/1/2021 | D30: 412 | F30: 5 | G30: 563.99842 | H30: 106.00158 | I30: 1.0058072 | K30: 5.1724138 | L30: 401
A31: 2021 | B31: 6 | C31: =DATE('MODELO 1'!$A31,'MODELO 1'!$B31,1) -> 6/1/2021 | D31: 549 | F31: 6 | G31: 563.82604 | H31: 72.17396 | I31: 0.68483025 | K31: 6.3218391 | L31: 402
A32: 2021 | B32: 7 | C32: =DATE('MODELO 1'!$A32,'MODELO 1'!$B32,1) -> 7/1/2021 | D32: 527 | F32: 7 | G32: 563.65922 | H32: 199.34078 | I32: 1.8914661 | K32: 7.4712644 | L32: 403
A33: 2021 | B33: 8 | C33: =DATE('MODELO 1'!$A33,'MODELO 1'!$B33,1) -> 8/1/2021 | D33: 631 | F33: 8 | G33: 563.48684 | H33: 241.51316 | I33: 2.2916232 | K33: 8.6206897 | L33: 406
A34: 2021 | B34: 9 | C34: =DATE('MODELO 1'!$A34,'MODELO 1'!$B34,1) -> 9/1/2021 | D34: 599 | F34: 9 | G34: 563.31445 | H34: 48.685547 | I34: 0.46195796 | K34: 9.7701149 | L34: 406
A35: 2021 | B35: 10 | C35: =DATE('MODELO 1'!$A35,'MODELO 1'!$B35,1) -> 10/1/2021 | D35: 557 | F35: 10 | G35: 563.14763 | H35: 115.85237 | I35: 1.0992774 | K35: 10.91954 | L35: 411
A36: 2021 | B36: 11 | C36: =DATE('MODELO 1'!$A36,'MODELO 1'!$B36,1) -> 11/1/2021 | D36: 613 | F36: 11 | G36: 562.97525 | H36: 61.024751 | I36: 0.57903981 | K36: 12.068966 | L36: 412
A37: 2021 | B37: 12 | C37: =DATE('MODELO 1'!$A37,'MODELO 1'!$B37,1) -> 12/1/2021 | D37: 733 | F37: 12 | G37: 562.80843 | H37: 137.19157 | I37: 1.3017567 | K37: 13.218391 | L37: 417
... A88: 2026 | B88: 3 | C88: =DATE('MODELO 1'!$A88,'MODELO 1'!$B88,1) -> 3/1/2026 | D88: 589 | F88: 63 | G88: 554.17817 | H88: -127.17817 | I88: -1.2067435 | K88: 71.83908 | L88: 613
F89: 64 | G89: 554.00579 | H89: 12.994211 | I89: 0.12329694 | K89: 72.988506 | L89: 614
F90: 65 | G90: 553.83897 | H90: 9.1610324 | I90: 0.086925425 | K90: 74.137931 | L90: 624
...

Sheet MODELO 2
A1: ANO | B1: MES | C1: DATA | D1: HEL | E1: DM1 | F1: DM2 | G1: DM3 | H1: DM4 | I1: DM5 | J1: DM6 | K1: DM7 | L1: DM8 | M1: DM9 | N1: DM10 | O1: DM11 | P1: DM12
A2: 2019 | B2: 1 | C2: =DATE('MODELO 2'!$A2,'MODELO 2'!$B2,1) -> 1/1/2019 | D2: 589 | E2: =IF('MODELO 2'!$B2=E$89,1,0) -> 1 | F2: =IF('MODELO 2'!$B2=F$89,1,0) -> 0 | G2: =IF('MODELO 2'!$B2=G$89,1,0) -> 0 | H2: =IF('MODELO 2'!$B2=H$89,1,0) -> 0 | I2: =IF('MODELO 2'!$B2=I$89,1,0) -> 0 | J2: =IF('MODELO 2'!$B2=J$89,1,0) -> 0 | K2: =IF('MODELO 2'!$B2=K$89,1,0) -> 0 | L2: =IF('MODELO 2'!$B2=L$89,1,0) -> 0 | ... P2: =IF('MODELO 2'!$B2=P$89,1,0) -> 0 | R2: SUMMARY OUTPUT
A3: 2019 | B3: 2 | C3: =DATE('MODELO 2'!$A3,'MODELO 2'!$B3,1) -> 2/1/2019 | D3: 601 | E3: =IF('MODELO 2'!$B3=E$89,1,0) -> 0 | F3: =IF('MODELO 2'!$B3=F$89,1,0) -> 1 | G3: =IF('MODELO 2'!$B3=G$89,1,0) -> 0 | H3: =IF('MODELO 2'!$B3=H$89,1,0) -> 0 | I3: =IF('MODELO 2'!$B3=I$89,1,0) -> 0 | J3: =IF('MODELO 2'!$B3=J$89,1,0) -> 0 | K3: =IF('MODELO 2'!$B3=K$89,1,0) -> 0 | L3: =IF('MODELO 2'!$B3=L$89,1,0) -> 0 | ... P3: =IF('MODELO 2'!$B3=P$89,1,0) -> 0
A4: 2019 | B4: 3 | C4: =DATE('MODELO 2'!$A4,'MODELO 2'!$B4,1) -> 3/1/2019 | D4: 579 | E4: =IF('MODELO 2'!$B4=E$89,1,0) -> 0 | F4: =IF('MODELO 2'!$B4=F$89,1,0) -> 0 | G4: =IF('MODELO 2'!$B4=G$89,1,0) -> 1 | H4: =IF('MODELO 2'!$B4=H$89,1,0) -> 0 | I4: =IF('MODELO 2'!$B4=I$89,1,0) -> 0 | J4: =IF('MODELO 2'!$B4=J$89,1,0) -> 0 | K4: =IF('MODELO 2'!$B4=K$89,1,0) -> 0 | L4: =IF('MODELO 2'!$B4=L$89,1,0) -> 0 | ... P4: =IF('MODELO 2'!$B4=P$89,1,0) -> 0 | R4: Regression Statistics
A5: 2019 | B5: 4 | C5: =DATE('MODELO 2'!$A5,'MODELO 2'!$B5,1) -> 4/1/2019 | D5: 614 | E5: =IF('MODELO 2'!$B5=E$89,1,0) -> 0 | F5: =IF('MODELO 2'!$B5=F$89,1,0) -> 0 | G5: =IF('MODELO 2'!$B5=G$89,1,0) -> 0 | H5: =IF('MODELO 2'!$B5=H$89,1,0) -> 1 | I5: =IF('MODELO 2'!$B5=I$89,1,0) -> 0 | J5: =IF('MODELO 2'!$B5=J$89,1,0) -> 0 | K5: =IF('MODELO 2'!$B5=K$89,1,0) -> 0 | L5: =IF('MODELO 2'!$B5=L$89,1,0) -> 0 | ... P5: =IF('MODELO 2'!$B5=P$89,1,0) -> 0 | R5: Multiple R | S5: 0.48515479
A6: 2019 | B6: 5 | C6: =DATE('MODELO 2'!$A6,'MODELO 2'!$B6,1) -> 5/1/2019 | D6: 670 | E6: =IF('MODELO 2'!$B6=E$89,1,0) -> 0 | F6: =IF('MODELO 2'!$B6=F$89,1,0) -> 0 | G6: =IF('MODELO 2'!$B6=G$89,1,0) -> 0 | H6: =IF('MODELO 2'!$B6=H$89,1,0) -> 0 | I6: =IF('MODELO 2'!$B6=I$89,1,0) -> 1 | J6: =IF('MODELO 2'!$B6=J$89,1,0) -> 0 | K6: =IF('MODELO 2'!$B6=K$89,1,0) -> 0 | L6: =IF('MODELO 2'!$B6=L$89,1,0) -> 0 | ... P6: =IF('MODELO 2'!$B6=P$89,1,0) -> 0 | R6: R Square | S6: 0.23537517
A7: 2019 | B7: 6 | C7: =DATE('MODELO 2'!$A7,'MODELO 2'!$B7,1) -> 6/1/2019 | D7: 636 | E7: =IF('MODELO 2'!$B7=E$89,1,0) -> 0 | F7: =IF('MODELO 2'!$B7=F$89,1,0) -> 0 | G7: =IF('MODELO 2'!$B7=G$89,1,0) -> 0 | H7: =IF('MODELO 2'!$B7=H$89,1,0) -> 0 | I7: =IF('MODELO 2'!$B7=I$89,1,0) -> 0 | J7: =IF('MODELO 2'!$B7=J$89,1,0) -> 1 | K7: =IF('MODELO 2'!$B7=K$89,1,0) -> 0 | L7: =IF('MODELO 2'!$B7=L$89,1,0) -> 0 | ... P7: =IF('MODELO 2'!$B7=P$89,1,0) -> 0 | R7: Adjusted R Square | S7: 0.10989686
A8: 2019 | B8: 7 | C8: =DATE('MODELO 2'!$A8,'MODELO 2'!$B8,1) -> 7/1/2019 | D8: 763 | E8: =IF('MODELO 2'!$B8=E$89,1,0) -> 0 | F8: =IF('MODELO 2'!$B8=F$89,1,0) -> 0 | G8: =IF('MODELO 2'!$B8=G$89,1,0) -> 0 | H8: =IF('MODELO 2'!$B8=H$89,1,0) -> 0 | I8: =IF('MODELO 2'!$B8=I$89,1,0) -> 0 | J8: =IF('MODELO 2'!$B8=J$89,1,0) -> 0 | K8: =IF('MODELO 2'!$B8=K$89,1,0) -> 1 | L8: =IF('MODELO 2'!$B8=L$89,1,0) -> 0 | ... P8: =IF('MODELO 2'!$B8=P$89,1,0) -> 0 | R8: Standard Error | S8: 98.763734
A9: 2019 | B9: 8 | C9: =DATE('MODELO 2'!$A9,'MODELO 2'!$B9,1) -> 8/1/2019 | D9: 805 | E9: =IF('MODELO 2'!$B9=E$89,1,0) -> 0 | F9: =IF('MODELO 2'!$B9=F$89,1,0) -> 0 | G9: =IF('MODELO 2'!$B9=G$89,1,0) -> 0 | H9: =IF('MODELO 2'!$B9=H$89,1,0) -> 0 | I9: =IF('MODELO 2'!$B9=I$89,1,0) -> 0 | J9: =IF('MODELO 2'!$B9=J$89,1,0) -> 0 | K9: =IF('MODELO 2'!$B9=K$89,1,0) -> 0 | L9: =IF('MODELO 2'!$B9=L$89,1,0) -> 1 | ... P9: =IF('MODELO 2'!$B9=P$89,1,0) -> 0 | R9: Observations | S9: 87
A10: 2019 | B10: 9 | C10: =DATE('MODELO 2'!$A10,'MODELO 2'!$B10,1) -> 9/1/2019 | D10: 612 | E10: =IF('MODELO 2'!$B10=E$89,1,0) -> 0 | F10: =IF('MODELO 2'!$B10=F$89,1,0) -> 0 | G10: =IF('MODELO 2'!$B10=G$89,1,0) -> 0 | H10: =IF('MODELO 2'!$B10=H$89,1,0) -> 0 | I10: =IF('MODELO 2'!$B10=I$89,1,0) -> 0 | J10: =IF('MODELO 2'!$B10=J$89,1,0) -> 0 | K10: =IF('MODELO 2'!$B10=K$89,1,0) -> 0 | L10: =IF('MODELO 2'!$B10=L$89,1,0) -> 0 | ... P10: =IF('MODELO 2'!$B10=P$89,1,0) -> 0
A11: 2019 | B11: 10 | C11: =DATE('MODELO 2'!$A11,'MODELO 2'!$B11,1) -> 10/1/2019 | D11: 679 | E11: =IF('MODELO 2'!$B11=E$89,1,0) -> 0 | F11: =IF('MODELO 2'!$B11=F$89,1,0) -> 0 | G11: =IF('MODELO 2'!$B11=G$89,1,0) -> 0 | H11: =IF('MODELO 2'!$B11=H$89,1,0) -> 0 | I11: =IF('MODELO 2'!$B11=I$89,1,0) -> 0 | J11: =IF('MODELO 2'!$B11=J$89,1,0) -> 0 | K11: =IF('MODELO 2'!$B11=K$89,1,0) -> 0 | L11: =IF('MODELO 2'!$B11=L$89,1,0) -> 0 | ... P11: =IF('MODELO 2'!$B11=P$89,1,0) -> 0 | R11: ANOVA
A12: 2019 | B12: 11 | C12: =DATE('MODELO 2'!$A12,'MODELO 2'!$B12,1) -> 11/1/2019 | D12: 624 | E12: =IF('MODELO 2'!$B12=E$89,1,0) -> 0 | F12: =IF('MODELO 2'!$B12=F$89,1,0) -> 0 | G12: =IF('MODELO 2'!$B12=G$89,1,0) -> 0 | H12: =IF('MODELO 2'!$B12=H$89,1,0) -> 0 | I12: =IF('MODELO 2'!$B12=I$89,1,0) -> 0 | J12: =IF('MODELO 2'!$B12=J$89,1,0) -> 0 | K12: =IF('MODELO 2'!$B12=K$89,1,0) -> 0 | L12: =IF('MODELO 2'!$B12=L$89,1,0) -> 0 | ... P12: =IF('MODELO 2'!$B12=P$89,1,0) -> 0 | S12: df | T12: SS | U12: MS | V12: F | W12: Significance F
A13: 2019 | B13: 12 | C13: =DATE('MODELO 2'!$A13,'MODELO 2'!$B13,1) -> 12/1/2019 | D13: 700 | E13: =IF('MODELO 2'!$B13=E$89,1,0) -> 0 | F13: =IF('MODELO 2'!$B13=F$89,1,0) -> 0 | G13: =IF('MODELO 2'!$B13=G$89,1,0) -> 0 | H13: =IF('MODELO 2'!$B13=H$89,1,0) -> 0 | I13: =IF('MODELO 2'!$B13=I$89,1,0) -> 0 | J13: =IF('MODELO 2'!$B13=J$89,1,0) -> 0 | K13: =IF('MODELO 2'!$B13=K$89,1,0) -> 0 | L13: =IF('MODELO 2'!$B13=L$89,1,0) -> 0 | ... P13: =IF('MODELO 2'!$B13=P$89,1,0) -> 1 | R13: Regression | S13: 12 | T13: 225200.07 | U13: 18766.672 | V13: 2.0988472 | W13: 0.02701813
A14: 2020 | B14: 1 | C14: =DATE('MODELO 2'!$A14,'MODELO 2'!$B14,1) -> 1/1/2020 | D14: 597 | E14: =IF('MODELO 2'!$B14=E$89,1,0) -> 1 | F14: =IF('MODELO 2'!$B14=F$89,1,0) -> 0 | G14: =IF('MODELO 2'!$B14=G$89,1,0) -> 0 | H14: =IF('MODELO 2'!$B14=H$89,1,0) -> 0 | I14: =IF('MODELO 2'!$B14=I$89,1,0) -> 0 | J14: =IF('MODELO 2'!$B14=J$89,1,0) -> 0 | K14: =IF('MODELO 2'!$B14=K$89,1,0) -> 0 | L14: =IF('MODELO 2'!$B14=L$89,1,0) -> 0 | ... P14: =IF('MODELO 2'!$B14=P$89,1,0) -> 0 | R14: Residual | S14: 75 | T14: 731570.64 | U14: 9754.2752
A15: 2020 | B15: 2 | C15: =DATE('MODELO 2'!$A15,'MODELO 2'!$B15,1) -> 2/1/2020 | D15: 526 | E15: =IF('MODELO 2'!$B15=E$89,1,0) -> 0 | F15: =IF('MODELO 2'!$B15=F$89,1,0) -> 1 | G15: =IF('MODELO 2'!$B15=G$89,1,0) -> 0 | H15: =IF('MODELO 2'!$B15=H$89,1,0) -> 0 | I15: =IF('MODELO 2'!$B15=I$89,1,0) -> 0 | J15: =IF('MODELO 2'!$B15=J$89,1,0) -> 0 | K15: =IF('MODELO 2'!$B15=K$89,1,0) -> 0 | L15: =IF('MODELO 2'!$B15=L$89,1,0) -> 0 | ... P15: =IF('MODELO 2'!$B15=P$89,1,0) -> 0 | R15: Total | S15: 87 | T15: 956770.71
A16: 2020 | B16: 3 | C16: =DATE('MODELO 2'!$A16,'MODELO 2'!$B16,1) -> 3/1/2020 | D16: 563 | E16: =IF('MODELO 2'!$B16=E$89,1,0) -> 0 | F16: =IF('MODELO 2'!$B16=F$89,1,0) -> 0 | G16: =IF('MODELO 2'!$B16=G$89,1,0) -> 1 | H16: =IF('MODELO 2'!$B16=H$89,1,0) -> 0 | I16: =IF('MODELO 2'!$B16=I$89,1,0) -> 0 | J16: =IF('MODELO 2'!$B16=J$89,1,0) -> 0 | K16: =IF('MODELO 2'!$B16=K$89,1,0) -> 0 | L16: =IF('MODELO 2'!$B16=L$89,1,0) -> 0 | ... P16: =IF('MODELO 2'!$B16=P$89,1,0) -> 0
A17: 2020 | B17: 4 | C17: =DATE('MODELO 2'!$A17,'MODELO 2'!$B17,1) -> 4/1/2020 | D17: 340 | E17: =IF('MODELO 2'!$B17=E$89,1,0) -> 0 | F17: =IF('MODELO 2'!$B17=F$89,1,0) -> 0 | G17: =IF('MODELO 2'!$B17=G$89,1,0) -> 0 | H17: =IF('MODELO 2'!$B17=H$89,1,0) -> 1 | I17: =IF('MODELO 2'!$B17=I$89,1,0) -> 0 | J17: =IF('MODELO 2'!$B17=J$89,1,0) -> 0 | K17: =IF('MODELO 2'!$B17=K$89,1,0) -> 0 | L17: =IF('MODELO 2'!$B17=L$89,1,0) -> 0 | ... P17: =IF('MODELO 2'!$B17=P$89,1,0) -> 0 | S17: Coefficients | T17: Standard Error | U17: t Stat | V17: P-value | W17: Lower 95% | X17: Upper 95% | Y17: Lower 95,0% | Z17: Upper 95,0%
A18: 2020 | B18: 5 | C18: =DATE('MODELO 2'!$A18,'MODELO 2'!$B18,1) -> 5/1/2020 | D18: 448 | E18: =IF('MODELO 2'!$B18=E$89,1,0) -> 0 | F18: =IF('MODELO 2'!$B18=F$89,1,0) -> 0 | G18: =IF('MODELO 2'!$B18=G$89,1,0) -> 0 | H18: =IF('MODELO 2'!$B18=H$89,1,0) -> 0 | I18: =IF('MODELO 2'!$B18=I$89,1,0) -> 1 | J18: =IF('MODELO 2'!$B18=J$89,1,0) -> 0 | K18: =IF('MODELO 2'!$B18=K$89,1,0) -> 0 | L18: =IF('MODELO 2'!$B18=L$89,1,0) -> 0 | ... P18: =IF('MODELO 2'!$B18=P$89,1,0) -> 0 | R18: Intercept | S18: 513.71429 | T18: 37.329183 | U18: 13.761734 | V18: 3.2666149e-22 | W18: 439.35074 | X18: 588.07783 | Y18: 439.35074 | Z18: 588.07783
A19: 2020 | B19: 6 | C19: =DATE('MODELO 2'!$A19,'MODELO 2'!$B19,1) -> 6/1/2020 | D19: 486 | E19: =IF('MODELO 2'!$B19=E$89,1,0) -> 0 | F19: =IF('MODELO 2'!$B19=F$89,1,0) -> 0 | G19: =IF('MODELO 2'!$B19=G$89,1,0) -> 0 | H19: =IF('MODELO 2'!$B19=H$89,1,0) -> 0 | I19: =IF('MODELO 2'!$B19=I$89,1,0) -> 0 | J19: =IF('MODELO 2'!$B19=J$89,1,0) -> 1 | K19: =IF('MODELO 2'!$B19=K$89,1,0) -> 0 | L19: =IF('MODELO 2'!$B19=L$89,1,0) -> 0 | ... P19: =IF('MODELO 2'!$B19=P$89,1,0) -> 0 | R19: DM1 | S19: -20.714286 | T19: 51.115089 | U19: -0.40524797 | V19: 0.68644891 | W19: -122.54076 | X19: 81.112193 | Y19: -122.54076 | Z19: 81.112193
A20: 2020 | B20: 7 | C20: =DATE('MODELO 2'!$A20,'MODELO 2'!$B20,1) -> 7/1/2020 | D20: 517 | E20: =IF('MODELO 2'!$B20=E$89,1,0) -> 0 | F20: =IF('MODELO 2'!$B20=F$89,1,0) -> 0 | G20: =IF('MODELO 2'!$B20=G$89,1,0) -> 0 | H20: =IF('MODELO 2'!$B20=H$89,1,0) -> 0 | I20: =IF('MODELO 2'!$B20=I$89,1,0) -> 0 | J20: =IF('MODELO 2'!$B20=J$89,1,0) -> 0 | K20: =IF('MODELO 2'!$B20=K$89,1,0) -> 1 | L20: =IF('MODELO 2'!$B20=L$89,1,0) -> 0 | ... P20: =IF('MODELO 2'!$B20=P$89,1,0) -> 0 | R20: DM2 | S20: -34.214286 | T20: 51.115089 | U20: -0.66935785 | V20: 0.50532263 | W20: -136.04076 | X20: 67.612193 | Y20: -136.04076 | Z20: 67.612193
A21: 2020 | B21: 8 | C21: =DATE('MODELO 2'!$A21,'MODELO 2'!$B21,1) -> 8/1/2020 | D21: 402 | E21: =IF('MODELO 2'!$B21=E$89,1,0) -> 0 | F21: =IF('MODELO 2'!$B21=F$89,1,0) -> 0 | G21: =IF('MODELO 2'!$B21=G$89,1,0) -> 0 | H21: =IF('MODELO 2'!$B21=H$89,1,0) -> 0 | I21: =IF('MODELO 2'!$B21=I$89,1,0) -> 0 | J21: =IF('MODELO 2'!$B21=J$89,1,0) -> 0 | K21: =IF('MODELO 2'!$B21=K$89,1,0) -> 0 | L21: =IF('MODELO 2'!$B21=L$89,1,0) -> 1 | ... P21: =IF('MODELO 2'!$B21=P$89,1,0) -> 0 | R21: DM3 | S21: 11.535714 | T21: 51.115089 | U21: 0.22568119 | V21: 0.82206324 | W21: -90.290764 | X21: 113.36219 | Y21: -90.290764 | Z21: 113.36219
A22: 2020 | B22: 9 | C22: =DATE('MODELO 2'!$A22,'MODELO 2'!$B22,1) -> 9/1/2020 | D22: 406 | E22: =IF('MODELO 2'!$B22=E$89,1,0) -> 0 | F22: =IF('MODELO 2'!$B22=F$89,1,0) -> 0 | G22: =IF('MODELO 2'!$B22=G$89,1,0) -> 0 | H22: =IF('MODELO 2'!$B22=H$89,1,0) -> 0 | I22: =IF('MODELO 2'!$B22=I$89,1,0) -> 0 | J22: =IF('MODELO 2'!$B22=J$89,1,0) -> 0 | K22: =IF('MODELO 2'!$B22=K$89,1,0) -> 0 | L22: =IF('MODELO 2'!$B22=L$89,1,0) -> 0 | ... P22: =IF('MODELO 2'!$B22=P$89,1,0) -> 0 | R22: DM4 | S22: 0 | T22: 0 | U22: 65535 | V22: #NUM! | W22: 0 | X22: 0 | Y22: 0 | Z22: 0
A23: 2020 | B23: 10 | C23: =DATE('MODELO 2'!$A23,'MODELO 2'!$B23,1) -> 10/1/2020 | D23: 456 | E23: =IF('MODELO 2'!$B23=E$89,1,0) -> 0 | F23: =IF('MODELO 2'!$B23=F$89,1,0) -> 0 | G23: =IF('MODELO 2'!$B23=G$89,1,0) -> 0 | H23: =IF('MODELO 2'!$B23=H$89,1,0) -> 0 | I23: =IF('MODELO 2'!$B23=I$89,1,0) -> 0 | J23: =IF('MODELO 2'!$B23=J$89,1,0) -> 0 | K23: =IF('MODELO 2'!$B23=K$89,1,0) -> 0 | L23: =IF('MODELO 2'!$B23=L$89,1,0) -> 0 | ... P23: =IF('MODELO 2'!$B23=P$89,1,0) -> 0 | R23: DM5 | S23: 58.428571 | T23: 52.791437 | U23: 1.1067812 | V23: #NUM! | W23: -46.737363 | X23: 163.59451 | Y23: -46.737363 | Z23: 163.59451
A24: 2020 | B24: 11 | C24: =DATE('MODELO 2'!$A24,'MODELO 2'!$B24,1) -> 11/1/2020 | D24: 417 | E24: =IF('MODELO 2'!$B24=E$89,1,0) -> 0 | F24: =IF('MODELO 2'!$B24=F$89,1,0) -> 0 | G24: =IF('MODELO 2'!$B24=G$89,1,0) -> 0 | H24: =IF('MODELO 2'!$B24=H$89,1,0) -> 0 | I24: =IF('MODELO 2'!$B24=I$89,1,0) -> 0 | J24: =IF('MODELO 2'!$B24=J$89,1,0) -> 0 | K24: =IF('MODELO 2'!$B24=K$89,1,0) -> 0 | L24: =IF('MODELO 2'!$B24=L$89,1,0) -> 0 | ... P24: =IF('MODELO 2'!$B24=P$89,1,0) -> 0 | R24: DM6 | S24: 103.42857 | T24: 52.791437 | U24: 1.9591922 | V24: 0.053807237 | W24: -1.7373632 | X24: 208.59451 | Y24: -1.7373632 | Z24: 208.59451
A25: 2020 | B25: 12 | C25: =DATE('MODELO 2'!$A25,'MODELO 2'!$B25,1) -> 12/1/2020 | D25: 490 | E25: =IF('MODELO 2'!$B25=E$89,1,0) -> 0 | F25: =IF('MODELO 2'!$B25=F$89,1,0) -> 0 | G25: =IF('MODELO 2'!$B25=G$89,1,0) -> 0 | H25: =IF('MODELO 2'!$B25=H$89,1,0) -> 0 | I25: =IF('MODELO 2'!$B25=I$89,1,0) -> 0 | J25: =IF('MODELO 2'!$B25=J$89,1,0) -> 0 | K25: =IF('MODELO 2'!$B25=K$89,1,0) -> 0 | L25: =IF('MODELO 2'!$B25=L$89,1,0) -> 0 | ... P25: =IF('MODELO 2'!$B25=P$89,1,0) -> 1 | R25: DM7 | S25: 108.71429 | T25: 52.791437 | U25: 2.0593167 | V25: 0.042935418 | W25: 3.5483511 | X25: 213.88022 | Y25: 3.5483511 | Z25: 213.88022
A26: 2021 | B26: 1 | C26: =DATE('MODELO 2'!$A26,'MODELO 2'!$B26,1) -> 1/1/2021 | D26: 401 | E26: =IF('MODELO 2'!$B26=E$89,1,0) -> 1 | F26: =IF('MODELO 2'!$B26=F$89,1,0) -> 0 | G26: =IF('MODELO 2'!$B26=G$89,1,0) -> 0 | H26: =IF('MODELO 2'!$B26=H$89,1,0) -> 0 | I26: =IF('MODELO 2'!$B26=I$89,1,0) -> 0 | J26: =IF('MODELO 2'!$B26=J$89,1,0) -> 0 | K26: =IF('MODELO 2'!$B26=K$89,1,0) -> 0 | L26: =IF('MODELO 2'!$B26=L$89,1,0) -> 0 | ... P26: =IF('MODELO 2'!$B26=P$89,1,0) -> 0 | R26: DM8 | S26: 107.28571 | T26: 52.791437 | U26: 2.032256 | V26: 0.045668907 | W26: 2.1197796 | X26: 212.45165 | Y26: 2.1197796 | Z26: 212.45165
A27: 2021 | B27: 2 | C27: =DATE('MODELO 2'!$A27,'MODELO 2'!$B27,1) -> 2/1/2021 | D27: 422 | E27: =IF('MODELO 2'!$B27=E$89,1,0) -> 0 | F27: =IF('MODELO 2'!$B27=F$89,1,0) -> 1 | G27: =IF('MODELO 2'!$B27=G$89,1,0) -> 0 | H27: =IF('MODELO 2'!$B27=H$89,1,0) -> 0 | I27: =IF('MODELO 2'!$B27=I$89,1,0) -> 0 | J27: =IF('MODELO 2'!$B27=J$89,1,0) -> 0 | K27: =IF('MODELO 2'!$B27=K$89,1,0) -> 0 | L27: =IF('MODELO 2'!$B27=L$89,1,0) -> 0 | ... P27: =IF('MODELO 2'!$B27=P$89,1,0) -> 0 | R27: DM9 | S27: 96.285714 | T27: 52.791437 | U27: 1.8238889 | V27: 0.072152506 | W27: -8.8802204 | X27: 201.45165 | Y27: -8.8802204 | Z27: 201.45165
A28: 2021 | B28: 3 | C28: =DATE('MODELO 2'!$A28,'MODELO 2'!$B28,1) -> 3/1/2021 | D28: 485 | E28: =IF('MODELO 2'!$B28=E$89,1,0) -> 0 | F28: =IF('MODELO 2'!$B28=F$89,1,0) -> 0 | G28: =IF('MODELO 2'!$B28=G$89,1,0) -> 1 | H28: =IF('MODELO 2'!$B28=H$89,1,0) -> 0 | I28: =IF('MODELO 2'!$B28=I$89,1,0) -> 0 | J28: =IF('MODELO 2'!$B28=J$89,1,0) -> 0 | K28: =IF('MODELO 2'!$B28=K$89,1,0) -> 0 | L28: =IF('MODELO 2'!$B28=L$89,1,0) -> 0 | ... P28: =IF('MODELO 2'!$B28=P$89,1,0) -> 0 | R28: DM10 | S28: 58.571429 | T28: 52.791437 | U28: 1.1094873 | V28: 0.27076486 | W28: -46.594506 | X28: 163.73736 | Y28: -46.594506 | Z28: 163.73736
A29: 2021 | B29: 4 | C29: =DATE('MODELO 2'!$A29,'MODELO 2'!$B29,1) -> 4/1/2021 | D29: 432 | E29: =IF('MODELO 2'!$B29=E$89,1,0) -> 0 | F29: =IF('MODELO 2'!$B29=F$89,1,0) -> 0 | G29: =IF('MODELO 2'!$B29=G$89,1,0) -> 0 | H29: =IF('MODELO 2'!$B29=H$89,1,0) -> 1 | I29: =IF('MODELO 2'!$B29=I$89,1,0) -> 0 | J29: =IF('MODELO 2'!$B29=J$89,1,0) -> 0 | K29: =IF('MODELO 2'!$B29=K$89,1,0) -> 0 | L29: =IF('MODELO 2'!$B29=L$89,1,0) -> 0 | ... P29: =IF('MODELO 2'!$B29=P$89,1,0) -> 0 | R29: DM11 | S29: -1.5714286 | T29: 52.791437 | U29: -0.029766732 | V29: 0.97633216 | W29: -106.73736 | X29: 103.59451 | Y29: -106.73736 | Z29: 103.59451
A30: 2021 | B30: 5 | C30: =DATE('MODELO 2'!$A30,'MODELO 2'!$B30,1) -> 5/1/2021 | D30: 412 | E30: =IF('MODELO 2'!$B30=E$89,1,0) -> 0 | F30: =IF('MODELO 2'!$B30=F$89,1,0) -> 0 | G30: =IF('MODELO 2'!$B30=G$89,1,0) -> 0 | H30: =IF('MODELO 2'!$B30=H$89,1,0) -> 0 | I30: =IF('MODELO 2'!$B30=I$89,1,0) -> 1 | J30: =IF('MODELO 2'!$B30=J$89,1,0) -> 0 | K30: =IF('MODELO 2'!$B30=K$89,1,0) -> 0 | L30: =IF('MODELO 2'!$B30=L$89,1,0) -> 0 | ... P30: =IF('MODELO 2'!$B30=P$89,1,0) -> 0 | R30: DM12 | S30: 61.285714 | T30: 52.791437 | U30: 1.1609026 | V30: 0.24936324 | W30: -43.88022 | X30: 166.45165 | Y30: -43.88022 | Z30: 166.45165
A31: 2021 | B31: 6 | C31: =DATE('MODELO 2'!$A31,'MODELO 2'!$B31,1) -> 6/1/2021 | D31: 549 | E31: =IF('MODELO 2'!$B31=E$89,1,0) -> 0 | F31: =IF('MODELO 2'!$B31=F$89,1,0) -> 0 | G31: =IF('MODELO 2'!$B31=G$89,1,0) -> 0 | H31: =IF('MODELO 2'!$B31=H$89,1,0) -> 0 | I31: =IF('MODELO 2'!$B31=I$89,1,0) -> 0 | J31: =IF('MODELO 2'!$B31=J$89,1,0) -> 1 | K31: =IF('MODELO 2'!$B31=K$89,1,0) -> 0 | L31: =IF('MODELO 2'!$B31=L$89,1,0) -> 0 | ... P31: =IF('MODELO 2'!$B31=P$89,1,0) -> 0
A32: 2021 | B32: 7 | C32: =DATE('MODELO 2'!$A32,'MODELO 2'!$B32,1) -> 7/1/2021 | D32: 527 | E32: =IF('MODELO 2'!$B32=E$89,1,0) -> 0 | F32: =IF('MODELO 2'!$B32=F$89,1,0) -> 0 | G32: =IF('MODELO 2'!$B32=G$89,1,0) -> 0 | H32: =IF('MODELO 2'!$B32=H$89,1,0) -> 0 | I32: =IF('MODELO 2'!$B32=I$89,1,0) -> 0 | J32: =IF('MODELO 2'!$B32=J$89,1,0) -> 0 | K32: =IF('MODELO 2'!$B32=K$89,1,0) -> 1 | L32: =IF('MODELO 2'!$B32=L$89,1,0) -> 0 | ... P32: =IF('MODELO 2'!$B32=P$89,1,0) -> 0
A33: 2021 | B33: 8 | C33: =DATE('MODELO 2'!$A33,'MODELO 2'!$B33,1) -> 8/1/2021 | D33: 631 | E33: =IF('MODELO 2'!$B33=E$89,1,0) -> 0 | F33: =IF('MODELO 2'!$B33=F$89,1,0) -> 0 | G33: =IF('MODELO 2'!$B33=G$89,1,0) -> 0 | H33: =IF('MODELO 2'!$B33=H$89,1,0) -> 0 | I33: =IF('MODELO 2'!$B33=I$89,1,0) -> 0 | J33: =IF('MODELO 2'!$B33=J$89,1,0) -> 0 | K33: =IF('MODELO 2'!$B33=K$89,1,0) -> 0 | L33: =IF('MODELO 2'!$B33=L$89,1,0) -> 1 | ... P33: =IF('MODELO 2'!$B33=P$89,1,0) -> 0
A34: 2021 | B34: 9 | C34: =DATE('MODELO 2'!$A34,'MODELO 2'!$B34,1) -> 9/1/2021 | D34: 599 | E34: =IF('MODELO 2'!$B34=E$89,1,0) -> 0 | F34: =IF('MODELO 2'!$B34=F$89,1,0) -> 0 | G34: =IF('MODELO 2'!$B34=G$89,1,0) -> 0 | H34: =IF('MODELO 2'!$B34=H$89,1,0) -> 0 | I34: =IF('MODELO 2'!$B34=I$89,1,0) -> 0 | J34: =IF('MODELO 2'!$B34=J$89,1,0) -> 0 | K34: =IF('MODELO 2'!$B34=K$89,1,0) -> 0 | L34: =IF('MODELO 2'!$B34=L$89,1,0) -> 0 | ... P34: =IF('MODELO 2'!$B34=P$89,1,0) -> 0 | R34: RESIDUAL OUTPUT | W34: PROBABILITY OUTPUT
A35: 2021 | B35: 10 | C35: =DATE('MODELO 2'!$A35,'MODELO 2'!$B35,1) -> 10/1/2021 | D35: 557 | E35: =IF('MODELO 2'!$B35=E$89,1,0) -> 0 | F35: =IF('MODELO 2'!$B35=F$89,1,0) -> 0 | G35: =IF('MODELO 2'!$B35=G$89,1,0) -> 0 | H35: =IF('MODELO 2'!$B35=H$89,1,0) -> 0 | I35: =IF('MODELO 2'!$B35=I$89,1,0) -> 0 | J35: =IF('MODELO 2'!$B35=J$89,1,0) -> 0 | K35: =IF('MODELO 2'!$B35=K$89,1,0) -> 0 | L35: =IF('MODELO 2'!$B35=L$89,1,0) -> 0 | ... P35: =IF('MODELO 2'!$B35=P$89,1,0) -> 0
A36: 2021 | B36: 11 | C36: =DATE('MODELO 2'!$A36,'MODELO 2'!$B36,1) -> 11/1/2021 | D36: 613 | E36: =IF('MODELO 2'!$B36=E$89,1,0) -> 0 | F36: =IF('MODELO 2'!$B36=F$89,1,0) -> 0 | G36: =IF('MODELO 2'!$B36=G$89,1,0) -> 0 | H36: =IF('MODELO 2'!$B36=H$89,1,0) -> 0 | I36: =IF('MODELO 2'!$B36=I$89,1,0) -> 0 | J36: =IF('MODELO 2'!$B36=J$89,1,0) -> 0 | K36: =IF('MODELO 2'!$B36=K$89,1,0) -> 0 | L36: =IF('MODELO 2'!$B36=L$89,1,0) -> 0 | ... P36: =IF('MODELO 2'!$B36=P$89,1,0) -> 0 | R36: Observation | S36: Predicted HEL | T36: Residuals | U36: Standard Residuals | W36: Percentile | X36: HEL
A37: 2021 | B37: 12 | C37: =DATE('MODELO 2'!$A37,'MODELO 2'!$B37,1) -> 12/1/2021 | D37: 733 | E37: =IF('MODELO 2'!$B37=E$89,1,0) -> 0 | F37: =IF('MODELO 2'!$B37=F$89,1,0) -> 0 | G37: =IF('MODELO 2'!$B37=G$89,1,0) -> 0 | H37: =IF('MODELO 2'!$B37=H$89,1,0) -> 0 | I37: =IF('MODELO 2'!$B37=I$89,1,0) -> 0 | J37: =IF('MODELO 2'!$B37=J$89,1,0) -> 0 | K37: =IF('MODELO 2'!$B37=K$89,1,0) -> 0 | L37: =IF('MODELO 2'!$B37=L$89,1,0) -> 0 | ... P37: =IF('MODELO 2'!$B37=P$89,1,0) -> 1 | R37: 1 | S37: 493 | T37: 96 | U37: 1.046894 | W37: 0.57471264 | X37: 340
A38: 2022 | B38: 1 | C38: =DATE('MODELO 2'!$A38,'MODELO 2'!$B38,1) -> 1/1/2022 | D38: 390 | E38: =IF('MODELO 2'!$B38=E$89,1,0) -> 1 | F38: =IF('MODELO 2'!$B38=F$89,1,0) -> 0 | G38: =IF('MODELO 2'!$B38=G$89,1,0) -> 0 | H38: =IF('MODELO 2'!$B38=H$89,1,0) -> 0 | I38: =IF('MODELO 2'!$B38=I$89,1,0) -> 0 | J38: =IF('MODELO 2'!$B38=J$89,1,0) -> 0 | K38: =IF('MODELO 2'!$B38=K$89,1,0) -> 0 | L38: =IF('MODELO 2'!$B38=L$89,1,0) -> 0 | ... P38: =IF('MODELO 2'!$B38=P$89,1,0) -> 0 | R38: 2 | S38: 479.5 | T38: 121.5 | U38: 1.3249753 | W38: 1.7241379 | X38: 368
A39: 2022 | B39: 2 | C39: =DATE('MODELO 2'!$A39,'MODELO 2'!$B39,1) -> 2/1/2022 | D39: 481 | E39: =IF('MODELO 2'!$B39=E$89,1,0) -> 0 | F39: =IF('MODELO 2'!$B39=F$89,1,0) -> 1 | G39: =IF('MODELO 2'!$B39=G$89,1,0) -> 0 | H39: =IF('MODELO 2'!$B39=H$89,1,0) -> 0 | I39: =IF('MODELO 2'!$B39=I$89,1,0) -> 0 | J39: =IF('MODELO 2'!$B39=J$89,1,0) -> 0 | K39: =IF('MODELO 2'!$B39=K$89,1,0) -> 0 | L39: =IF('MODELO 2'!$B39=L$89,1,0) -> 0 | ... P39: =IF('MODELO 2'!$B39=P$89,1,0) -> 0 | R39: 3 | S39: 525.25 | T39: 53.75 | U39: 0.58615161 | W39: 2.8735632 | X39: 386
A40: 2022 | B40: 3 | C40: =DATE('MODELO 2'!$A40,'MODELO 2'!$B40,1) -> 3/1/2022 | D40: 552 | E40: =IF('MODELO 2'!$B40=E$89,1,0) -> 0 | F40: =IF('MODELO 2'!$B40=F$89,1,0) -> 0 | G40: =IF('MODELO 2'!$B40=G$89,1,0) -> 1 | H40: =IF('MODELO 2'!$B40=H$89,1,0) -> 0 | I40: =IF('MODELO 2'!$B40=I$89,1,0) -> 0 | J40: =IF('MODELO 2'!$B40=J$89,1,0) -> 0 | K40: =IF('MODELO 2'!$B40=K$89,1,0) -> 0 | L40: =IF('MODELO 2'!$B40=L$89,1,0) -> 0 | ... P40: =IF('MODELO 2'!$B40=P$89,1,0) -> 0 | R40: 4 | S40: 513.71429 | T40: 100.28571 | U40: 1.0936304 | W40: 4.0229885 | X40: 390
...

Sheet MODELO 3
A1: ANO | B1: MES | C1: DATA | D1: HEL | E1: POP
A2: 2019 | B2: 1 | C2: =DATE('MODELO 3'!$A2,'MODELO 3'!$B2,1) -> 1/1/2019 | D2: 589 | E2: 3015000 | L2: SUMMARY OUTPUT
A3: 2019 | B3: 2 | C3: =DATE('MODELO 3'!$A3,'MODELO 3'!$B3,1) -> 2/1/2019 | D3: 601 | E3: 3015000
A4: 2019 | B4: 3 | C4: =DATE('MODELO 3'!$A4,'MODELO 3'!$B4,1) -> 3/1/2019 | D4: 579 | E4: 3015000 | L4: Regression Statistics
A5: 2019 | B5: 4 | C5: =DATE('MODELO 3'!$A5,'MODELO 3'!$B5,1) -> 4/1/2019 | D5: 614 | E5: 3015000 | L5: Multiple R | M5: 0.10708061
A6: 2019 | B6: 5 | C6: =DATE('MODELO 3'!$A6,'MODELO 3'!$B6,1) -> 5/1/2019 | D6: 670 | E6: 3015000 | L6: R Square | M6: 0.011466257
A7: 2019 | B7: 6 | C7: =DATE('MODELO 3'!$A7,'MODELO 3'!$B7,1) -> 6/1/2019 | D7: 636 | E7: 3015000 | L7: Adjusted R Square | M7: -0.0026556539
A8: 2019 | B8: 7 | C8: =DATE('MODELO 3'!$A8,'MODELO 3'!$B8,1) -> 7/1/2019 | D8: 763 | E8: 3015000 | L8: Standard Error | M8: 106.78503
A9: 2019 | B9: 8 | C9: =DATE('MODELO 3'!$A9,'MODELO 3'!$B9,1) -> 8/1/2019 | D9: 805 | E9: 3015000 | L9: Observations | M9: 72
A10: 2019 | B10: 9 | C10: =DATE('MODELO 3'!$A10,'MODELO 3'!$B10,1) -> 9/1/2019 | D10: 612 | E10: 3015000
A11: 2019 | B11: 10 | C11: =DATE('MODELO 3'!$A11,'MODELO 3'!$B11,1) -> 10/1/2019 | D11: 679 | E11: 3015000 | L11: ANOVA
A12: 2019 | B12: 11 | C12: =DATE('MODELO 3'!$A12,'MODELO 3'!$B12,1) -> 11/1/2019 | D12: 624 | E12: 3015000 | M12: df | N12: SS | O12: MS | P12: F | Q12: Significance F
A13: 2019 | B13: 12 | C13: =DATE('MODELO 3'!$A13,'MODELO 3'!$B13,1) -> 12/1/2019 | D13: 700 | E13: 3015000 | L13: Regression | M13: 1 | N13: 9258.6773 | O13: 9258.6773 | P13: 0.81194798 | Q13: 0.37063479
A14: 2020 | B14: 1 | C14: =DATE('MODELO 3'!$A14,'MODELO 3'!$B14,1) -> 1/1/2020 | D14: 597 | E14: 3052546 | L14: Residual | M14: 70 | N14: 798212.98 | O14: 11403.043
A15: 2020 | B15: 2 | C15: =DATE('MODELO 3'!$A15,'MODELO 3'!$B15,1) -> 2/1/2020 | D15: 526 | E15: 3052546 | L15: Total | M15: 71 | N15: 807471.65
A16: 2020 | B16: 3 | C16: =DATE('MODELO 3'!$A16,'MODELO 3'!$B16,1) -> 3/1/2020 | D16: 563 | E16: 3052546
A17: 2020 | B17: 4 | C17: =DATE('MODELO 3'!$A17,'MODELO 3'!$B17,1) -> 4/1/2020 | D17: 340 | E17: 3052546 | M17: Coefficients | N17: Standard Error | O17: t Stat | P17: P-value | Q17: Lower 95% | R17: Upper 95% | S17: Lower 95,0% | T17: Upper 95,0%
A18: 2020 | B18: 5 | C18: =DATE('MODELO 3'!$A18,'MODELO 3'!$B18,1) -> 5/1/2020 | D18: 448 | E18: 3052546 | L18: Intercept | M18: 1100.4396 | N18: 603.86015 | O18: 1.8223419 | P18: 0.072674437 | Q18: -103.92147 | R18: 2304.8007 | S18: -103.92147 | T18: 2304.8007
A19: 2020 | B19: 6 | C19: =DATE('MODELO 3'!$A19,'MODELO 3'!$B19,1) -> 6/1/2020 | D19: 486 | E19: 3052546 | L19: POP | M19: -0.00017491504 | N19: 0.00019411677 | O19: -0.90108156 | P19: 0.37063479 | Q19: -0.00056206873 | R19: 0.00021223865 | S19: -0.00056206873 | T19: 0.00021223865
A20: 2020 | B20: 7 | C20: =DATE('MODELO 3'!$A20,'MODELO 3'!$B20,1) -> 7/1/2020 | D20: 517 | E20: 3052546
A21: 2020 | B21: 8 | C21: =DATE('MODELO 3'!$A21,'MODELO 3'!$B21,1) -> 8/1/2020 | D21: 402 | E21: 3052546
A22: 2020 | B22: 9 | C22: =DATE('MODELO 3'!$A22,'MODELO 3'!$B22,1) -> 9/1/2020 | D22: 406 | E22: 3052546
A23: 2020 | B23: 10 | C23: =DATE('MODELO 3'!$A23,'MODELO 3'!$B23,1) -> 10/1/2020 | D23: 456 | E23: 3052546 | L23: RESIDUAL OUTPUT | Q23: PROBABILITY OUTPUT
A24: 2020 | B24: 11 | C24: =DATE('MODELO 3'!$A24,'MODELO 3'!$B24,1) -> 11/1/2020 | D24: 417 | E24: 3052546
A25: 2020 | B25: 12 | C25: =DATE('MODELO 3'!$A25,'MODELO 3'!$B25,1) -> 12/1/2020 | D25: 490 | E25: 3052546 | L25: Observation | M25: Predicted HEL | N25: Residuals | O25: Standard Residuals | Q25: Percentile | R25: HEL
A26: 2021 | B26: 1 | C26: =DATE('MODELO 3'!$A26,'MODELO 3'!$B26,1) -> 1/1/2021 | D26: 401 | E26: 3091667 | L26: 1 | M26: 573.07078 | N26: 15.929223 | O26: 0.15023266 | Q26: 0.69444444 | R26: 340
A27: 2021 | B27: 2 | C27: =DATE('MODELO 3'!$A27,'MODELO 3'!$B27,1) -> 2/1/2021 | D27: 422 | E27: 3091667 | L27: 2 | M27: 573.07078 | N27: 27.929223 | O27: 0.2634078 | Q27: 2.0833333 | R27: 368
A28: 2021 | B28: 3 | C28: =DATE('MODELO 3'!$A28,'MODELO 3'!$B28,1) -> 3/1/2021 | D28: 485 | E28: 3091667 | L28: 3 | M28: 573.07078 | N28: 5.9292227 | O28: 0.05592005 | Q28: 3.4722222 | R28: 390
A29: 2021 | B29: 4 | C29: =DATE('MODELO 3'!$A29,'MODELO 3'!$B29,1) -> 4/1/2021 | D29: 432 | E29: 3091667 | L29: 4 | M29: 573.07078 | N29: 40.929223 | O29: 0.3860142 | Q29: 4.8611111 | R29: 401
A30: 2021 | B30: 5 | C30: =DATE('MODELO 3'!$A30,'MODELO 3'!$B30,1) -> 5/1/2021 | D30: 412 | E30: 3091667 | L30: 5 | M30: 573.07078 | N30: 96.929223 | O30: 0.91416484 | Q30: 6.25 | R30: 402
A31: 2021 | B31: 6 | C31: =DATE('MODELO 3'!$A31,'MODELO 3'!$B31,1) -> 6/1/2021 | D31: 549 | E31: 3091667 | L31: 6 | M31: 573.07078 | N31: 62.929223 | O31: 0.59350195 | Q31: 7.6388889 | R31: 403
A32: 2021 | B32: 7 | C32: =DATE('MODELO 3'!$A32,'MODELO 3'!$B32,1) -> 7/1/2021 | D32: 527 | E32: 3091667 | L32: 7 | M32: 573.07078 | N32: 189.92922 | O32: 1.7912721 | Q32: 9.0277778 | R32: 406
A33: 2021 | B33: 8 | C33: =DATE('MODELO 3'!$A33,'MODELO 3'!$B33,1) -> 8/1/2021 | D33: 631 | E33: 3091667 | L33: 8 | M33: 573.07078 | N33: 231.92922 | O33: 2.1873851 | Q33: 10.416667 | R33: 412
A34: 2021 | B34: 9 | C34: =DATE('MODELO 3'!$A34,'MODELO 3'!$B34,1) -> 9/1/2021 | D34: 599 | E34: 3091667 | L34: 9 | M34: 573.07078 | N34: 38.929223 | O34: 0.36715168 | Q34: 11.805556 | R34: 417
A35: 2021 | B35: 10 | C35: =DATE('MODELO 3'!$A35,'MODELO 3'!$B35,1) -> 10/1/2021 | D35: 557 | E35: 3091667 | L35: 10 | M35: 573.07078 | N35: 105.92922 | O35: 0.99904619 | Q35: 13.194444 | R35: 422
A36: 2021 | B36: 11 | C36: =DATE('MODELO 3'!$A36,'MODELO 3'!$B36,1) -> 11/1/2021 | D36: 613 | E36: 3091667 | L36: 11 | M36: 573.07078 | N36: 50.929223 | O36: 0.48032681 | Q36: 14.583333 | R36: 427
A37: 2021 | B37: 12 | C37: =DATE('MODELO 3'!$A37,'MODELO 3'!$B37,1) -> 12/1/2021 | D37: 733 | E37: 3091667 | L37: 12 | M37: 573.07078 | N37: 126.92922 | O37: 1.1971027 | Q37: 15.972222 | R37: 427
... A73: 2024 | B73: 12 | C73: =DATE('MODELO 3'!$A73,'MODELO 3'!$B73,1) -> 12/1/2024 | D73: 607 | E73: 3204070 | L73: 48 | M73: 552.9531 | N73: -11.953099 | O73: -0.1127328 | Q73: 65.972222 | R73: 601
L74: 49 | M74: 546.39588 | N74: -50.395884 | O74: -0.47529675 | Q74: 67.361111 | R74: 602
L75: 50 | M75: 546.39588 | N75: -99.395884 | O75: -0.93742856 | Q75: 68.75 | R75: 607
...

Sheet MODELO 4
A1: ANO | B1: MES | C1: DATA | D1: HEL | E1: HELIPT | F1: PAND
A2: 2019 | B2: 1 | C2: =DATE('MODELO 4'!$A2,'MODELO 4'!$B2,1) -> 1/1/2019 | D2: 589 | E2: 6 | F2: 0 | K2: SUMMARY OUTPUT
A3: 2019 | B3: 2 | C3: =DATE('MODELO 4'!$A3,'MODELO 4'!$B3,1) -> 2/1/2019 | D3: 601 | E3: 6 | F3: 0
A4: 2019 | B4: 3 | C4: =DATE('MODELO 4'!$A4,'MODELO 4'!$B4,1) -> 3/1/2019 | D4: 579 | E4: 6 | F4: 0 | K4: Regression Statistics
A5: 2019 | B5: 4 | C5: =DATE('MODELO 4'!$A5,'MODELO 4'!$B5,1) -> 4/1/2019 | D5: 614 | E5: 6 | F5: 0 | K5: Multiple R | L5: 0.47261334
A6: 2019 | B6: 5 | C6: =DATE('MODELO 4'!$A6,'MODELO 4'!$B6,1) -> 5/1/2019 | D6: 670 | E6: 6 | F6: 0 | K6: R Square | L6: 0.22336337
A7: 2019 | B7: 6 | C7: =DATE('MODELO 4'!$A7,'MODELO 4'!$B7,1) -> 6/1/2019 | D7: 636 | E7: 6 | F7: 0 | K7: Adjusted R Square | L7: 0.20487203
A8: 2019 | B8: 7 | C8: =DATE('MODELO 4'!$A8,'MODELO 4'!$B8,1) -> 7/1/2019 | D8: 763 | E8: 6 | F8: 0 | K8: Standard Error | L8: 94.053124
A9: 2019 | B9: 8 | C9: =DATE('MODELO 4'!$A9,'MODELO 4'!$B9,1) -> 8/1/2019 | D9: 805 | E9: 6 | F9: 0 | K9: Observations | L9: 87
A10: 2019 | B10: 9 | C10: =DATE('MODELO 4'!$A10,'MODELO 4'!$B10,1) -> 9/1/2019 | D10: 612 | E10: 6 | F10: 0
A11: 2019 | B11: 10 | C11: =DATE('MODELO 4'!$A11,'MODELO 4'!$B11,1) -> 10/1/2019 | D11: 679 | E11: 7 | F11: 0 | K11: ANOVA
A12: 2019 | B12: 11 | C12: =DATE('MODELO 4'!$A12,'MODELO 4'!$B12,1) -> 11/1/2019 | D12: 624 | E12: 7 | F12: 0 | L12: df | M12: SS | N12: MS | O12: F | P12: Significance F
A13: 2019 | B13: 12 | C13: =DATE('MODELO 4'!$A13,'MODELO 4'!$B13,1) -> 12/1/2019 | D13: 700 | E13: 7 | F13: 0 | K13: Regression | L13: 2 | M13: 213707.53 | N13: 106853.77 | O13: 12.079345 | P13: 2.4499119e-05
A14: 2020 | B14: 1 | C14: =DATE('MODELO 4'!$A14,'MODELO 4'!$B14,1) -> 1/1/2020 | D14: 597 | E14: 7 | F14: 0 | K14: Residual | L14: 84 | M14: 743063.18 | N14: 8845.9902
A15: 2020 | B15: 2 | C15: =DATE('MODELO 4'!$A15,'MODELO 4'!$B15,1) -> 2/1/2020 | D15: 526 | E15: 7 | F15: 0 | K15: Total | L15: 86 | M15: 956770.71
A16: 2020 | B16: 3 | C16: =DATE('MODELO 4'!$A16,'MODELO 4'!$B16,1) -> 3/1/2020 | D16: 563 | E16: 7 | F16: 0
A17: 2020 | B17: 4 | C17: =DATE('MODELO 4'!$A17,'MODELO 4'!$B17,1) -> 4/1/2020 | D17: 340 | E17: 7 | F17: 1 | L17: Coefficients | M17: Standard Error | N17: t Stat | O17: P-value | P17: Lower 95% | Q17: Upper 95% | R17: Lower 95,0% | S17: Upper 95,0%
A18: 2020 | B18: 5 | C18: =DATE('MODELO 4'!$A18,'MODELO 4'!$B18,1) -> 5/1/2020 | D18: 448 | E18: 7 | F18: 1 | K18: Intercept | L18: 509.7049 | M18: 45.311236 | N18: 11.248974 | O18: 1.9297345e-18 | P18: 419.59854 | Q18: 599.81126 | R18: 419.59854 | S18: 599.81126
A19: 2020 | B19: 6 | C19: =DATE('MODELO 4'!$A19,'MODELO 4'!$B19,1) -> 6/1/2020 | D19: 486 | E19: 7 | F19: 1 | K19: HELIPT | L19: 19.921109 | M19: 5.9772016 | N19: 3.3328488 | O19: 0.0012800228 | P19: 8.0347883 | Q19: 31.80743 | R19: 8.0347883 | S19: 31.80743
A20: 2020 | B20: 7 | C20: =DATE('MODELO 4'!$A20,'MODELO 4'!$B20,1) -> 7/1/2020 | D20: 517 | E20: 7 | F20: 1 | K20: PAND | L20: -174.79247 | M20: 35.571465 | N20: -4.9138397 | O20: 4.3582453e-06 | P20: -245.53023 | Q20: -104.05472 | R20: -245.53023 | S20: -104.05472
A21: 2020 | B21: 8 | C21: =DATE('MODELO 4'!$A21,'MODELO 4'!$B21,1) -> 8/1/2020 | D21: 402 | E21: 7 | F21: 1
A22: 2020 | B22: 9 | C22: =DATE('MODELO 4'!$A22,'MODELO 4'!$B22,1) -> 9/1/2020 | D22: 406 | E22: 7 | F22: 1
A23: 2020 | B23: 10 | C23: =DATE('MODELO 4'!$A23,'MODELO 4'!$B23,1) -> 10/1/2020 | D23: 456 | E23: 7 | F23: 1
A24: 2020 | B24: 11 | C24: =DATE('MODELO 4'!$A24,'MODELO 4'!$B24,1) -> 11/1/2020 | D24: 417 | E24: 8 | F24: 1 | K24: RESIDUAL OUTPUT
A25: 2020 | B25: 12 | C25: =DATE('MODELO 4'!$A25,'MODELO 4'!$B25,1) -> 12/1/2020 | D25: 490 | E25: 8 | F25: 1
A26: 2021 | B26: 1 | C26: =DATE('MODELO 4'!$A26,'MODELO 4'!$B26,1) -> 1/1/2021 | D26: 401 | E26: 8 | F26: 1 | K26: Observation | L26: Predicted HEL | M26: Residuals | N26: Standard Residuals
A27: 2021 | B27: 2 | C27: =DATE('MODELO 4'!$A27,'MODELO 4'!$B27,1) -> 2/1/2021 | D27: 422 | E27: 8 | F27: 1 | K27: 1 | L27: 629.23156 | M27: -40.231556 | N27: -0.43281588
A28: 2021 | B28: 3 | C28: =DATE('MODELO 4'!$A28,'MODELO 4'!$B28,1) -> 3/1/2021 | D28: 485 | E28: 8 | F28: 1 | K28: 2 | L28: 629.23156 | M28: -28.231556 | N28: -0.30371845
A29: 2021 | B29: 4 | C29: =DATE('MODELO 4'!$A29,'MODELO 4'!$B29,1) -> 4/1/2021 | D29: 432 | E29: 8 | F29: 1 | K29: 3 | L29: 629.23156 | M29: -50.231556 | N29: -0.54039707
A30: 2021 | B30: 5 | C30: =DATE('MODELO 4'!$A30,'MODELO 4'!$B30,1) -> 5/1/2021 | D30: 412 | E30: 8 | F30: 1 | K30: 4 | L30: 629.23156 | M30: -15.231556 | N30: -0.1638629
A31: 2021 | B31: 6 | C31: =DATE('MODELO 4'!$A31,'MODELO 4'!$B31,1) -> 6/1/2021 | D31: 549 | E31: 8 | F31: 1 | K31: 5 | L31: 629.23156 | M31: 40.768444 | N31: 0.43859178
A32: 2021 | B32: 7 | C32: =DATE('MODELO 4'!$A32,'MODELO 4'!$B32,1) -> 7/1/2021 | D32: 527 | E32: 8 | F32: 1 | K32: 6 | L32: 629.23156 | M32: 6.7684437 | N32: 0.072815725
A33: 2021 | B33: 8 | C33: =DATE('MODELO 4'!$A33,'MODELO 4'!$B33,1) -> 8/1/2021 | D33: 631 | E33: 8 | F33: 1 | K33: 7 | L33: 629.23156 | M33: 133.76844 | N33: 1.4390969
A34: 2021 | B34: 9 | C34: =DATE('MODELO 4'!$A34,'MODELO 4'!$B34,1) -> 9/1/2021 | D34: 599 | E34: 8 | F34: 1 | K34: 8 | L34: 629.23156 | M34: 175.76844 | N34: 1.8909379
A35: 2021 | B35: 10 | C35: =DATE('MODELO 4'!$A35,'MODELO 4'!$B35,1) -> 10/1/2021 | D35: 557 | E35: 9 | F35: 1 | K35: 9 | L35: 629.23156 | M35: -17.231556 | N35: -0.18537914
A36: 2021 | B36: 11 | C36: =DATE('MODELO 4'!$A36,'MODELO 4'!$B36,1) -> 11/1/2021 | D36: 613 | E36: 9 | F36: 1 | K36: 10 | L36: 649.15267 | M36: 29.847334 | N36: 0.32110118
A37: 2021 | B37: 12 | C37: =DATE('MODELO 4'!$A37,'MODELO 4'!$B37,1) -> 12/1/2021 | D37: 733 | E37: 9 | F37: 1 | K37: 11 | L37: 649.15267 | M37: -25.152666 | N37: -0.27059538
A38: 2022 | B38: 1 | C38: =DATE('MODELO 4'!$A38,'MODELO 4'!$B38,1) -> 1/1/2022 | D38: 390 | E38: 9 | F38: 1 | K38: 12 | L38: 649.15267 | M38: 50.847334 | N38: 0.54702169
... A88: 2026 | B88: 3 | C88: =DATE('MODELO 4'!$A88,'MODELO 4'!$B88,1) -> 3/1/2026 | D88: 589 | E88: 12 | F88: 1 | K88: 62 | L88: 573.96574 | M88: -170.96574 | N88: -1.8392698
K89: 63 | L89: 573.96574 | M89: -146.96574 | N89: -1.5810749
...

Sheet MODELO 5
A1: ANO | B1: MES | C1: DATA | D1: HEL | E1: HELIPT | F1: QAVREF
A2: 2022 | B2: 3 | C2: =DATE('MODELO 5'!$A2,'MODELO 5'!$B2,1) -> 3/1/2022 | D2: 552 | E2: 10 | F2: 4.9680865 | I2: SUMMARY OUTPUT
A3: 2022 | B3: 4 | C3: =DATE('MODELO 5'!$A3,'MODELO 5'!$B3,1) -> 4/1/2022 | D3: 539 | E3: 10 | F3: 4.9159763
A4: 2023 | B4: 7 | C4: =DATE('MODELO 5'!$A4,'MODELO 5'!$B4,1) -> 7/1/2023 | D4: 657 | E4: 12 | F4: 3.9273094 | I4: Regression Statistics
A5: 2023 | B5: 8 | C5: =DATE('MODELO 5'!$A5,'MODELO 5'!$B5,1) -> 8/1/2023 | D5: 625 | E5: 12 | F5: 4.0726881 | I5: Multiple R | J5: 0.17794485
A6: 2023 | B6: 9 | C6: =DATE('MODELO 5'!$A6,'MODELO 5'!$B6,1) -> 9/1/2023 | D6: 685 | E6: 12 | F6: 4.706179 | I6: R Square | J6: 0.03166437
A7: 2023 | B7: 10 | C7: =DATE('MODELO 5'!$A7,'MODELO 5'!$B7,1) -> 10/1/2023 | D7: 658 | E7: 12 | F7: 5.0914584 | I7: Adjusted R Square | J7: 0.0023208656
A8: 2023 | B8: 11 | C8: =DATE('MODELO 5'!$A8,'MODELO 5'!$B8,1) -> 11/1/2023 | D8: 632 | E8: 12 | F8: 5.0316118 | I8: Standard Error | J8: 95.745622
A9: 2023 | B9: 12 | C9: =DATE('MODELO 5'!$A9,'MODELO 5'!$B9,1) -> 12/1/2023 | D9: 543 | E9: 12 | F9: 4.7631641 | I9: Observations | J9: 35
A10: 2024 | B10: 1 | C10: =DATE('MODELO 5'!$A10,'MODELO 5'!$B10,1) -> 1/1/2024 | D10: 502 | E10: 12 | F10: 4.2482129
A11: 2024 | B11: 2 | C11: =DATE('MODELO 5'!$A11,'MODELO 5'!$B11,1) -> 2/1/2024 | D11: 403 | E11: 12 | F11: 4.1887436 | I11: ANOVA
A12: 2024 | B12: 3 | C12: =DATE('MODELO 5'!$A12,'MODELO 5'!$B12,1) -> 3/1/2024 | D12: 427 | E12: 12 | F12: 4.4571764 | J12: df | K12: SS | L12: MS | M12: F | N12: Significance F
A13: 2024 | B13: 4 | C13: =DATE('MODELO 5'!$A13,'MODELO 5'!$B13,1) -> 4/1/2024 | D13: 567 | E13: 12 | F13: 4.4505587 | I13: Regression | J13: 1 | K13: 9892.2874 | L13: 9892.2874 | M13: 1.079093 | N13: 0.30645234
A14: 2024 | B14: 5 | C14: =DATE('MODELO 5'!$A14,'MODELO 5'!$B14,1) -> 5/1/2024 | D14: 563 | E14: 12 | F14: 4.5139893 | I14: Residual | J14: 33 | K14: 302518.4 | L14: 9167.2242
A15: 2024 | B15: 6 | C15: =DATE('MODELO 5'!$A15,'MODELO 5'!$B15,1) -> 6/1/2024 | D15: 573 | E15: 12 | F15: 4.2664929 | I15: Total | J15: 34 | K15: 312410.69
A16: 2024 | B16: 7 | C16: =DATE('MODELO 5'!$A16,'MODELO 5'!$B16,1) -> 7/1/2024 | D16: 600 | E16: 12 | F16: 4.3151627
A17: 2024 | B17: 8 | C17: =DATE('MODELO 5'!$A17,'MODELO 5'!$B17,1) -> 8/1/2024 | D17: 677 | E17: 12 | F17: 4.4957668 | J17: Coefficients | K17: Standard Error | L17: t Stat | M17: P-value | N17: Lower 95% | O17: Upper 95% | P17: Lower 95,0% | Q17: Upper 95,0%
A18: 2024 | B18: 9 | C18: =DATE('MODELO 5'!$A18,'MODELO 5'!$B18,1) -> 9/1/2024 | D18: 590 | E18: 12 | F18: 4.3352168 | I18: Intercept | J18: 405.53 | K18: 150.29032 | L18: 2.6983109 | M18: 0.010897684 | N18: 99.762047 | O18: 711.29795 | P18: 99.762047 | Q18: 711.29795
A19: 2024 | B19: 10 | C19: =DATE('MODELO 5'!$A19,'MODELO 5'!$B19,1) -> 10/1/2024 | D19: 428 | E19: 12 | F19: 3.9844986 | I19: QAVREF | J19: 37.228958 | K19: 35.838634 | L19: 1.038794 | M19: 0.30645234 | N19: -35.685291 | O19: 110.14321 | P19: -35.685291 | Q19: 110.14321
A20: 2024 | B20: 11 | C20: =DATE('MODELO 5'!$A20,'MODELO 5'!$B20,1) -> 11/1/2024 | D20: 368 | E20: 12 | F20: 3.9123095
A21: 2024 | B21: 12 | C21: =DATE('MODELO 5'!$A21,'MODELO 5'!$B21,1) -> 12/1/2024 | D21: 607 | E21: 12 | F21: 4.0059905
A22: 2025 | B22: 1 | C22: =DATE('MODELO 5'!$A22,'MODELO 5'!$B22,1) -> 1/1/2025 | D22: 583 | E22: 12 | F22: 4.1817297
A23: 2025 | B23: 2 | C23: =DATE('MODELO 5'!$A23,'MODELO 5'!$B23,1) -> 2/1/2025 | D23: 550 | E23: 12 | F23: 4.5288177 | I23: RESIDUAL OUTPUT
A24: 2025 | B24: 3 | C24: =DATE('MODELO 5'!$A24,'MODELO 5'!$B24,1) -> 3/1/2025 | D24: 580 | E24: 12 | F24: 4.2498737
A25: 2025 | B25: 4 | C25: =DATE('MODELO 5'!$A25,'MODELO 5'!$B25,1) -> 4/1/2025 | D25: 522 | E25: 12 | F25: 3.8907303 | I25: Observation | J25: Predicted HEL | K25: Residuals | L25: Standard Residuals
A26: 2025 | B26: 5 | C26: =DATE('MODELO 5'!$A26,'MODELO 5'!$B26,1) -> 5/1/2025 | D26: 598 | E26: 12 | F26: 3.859696 | I26: 1 | J26: 590.48668 | K26: -38.486685 | L26: -0.40801306
A27: 2025 | B27: 6 | C27: =DATE('MODELO 5'!$A27,'MODELO 5'!$B27,1) -> 6/1/2025 | D27: 594 | E27: 12 | F27: 3.6218383 | I27: 2 | J27: 588.54668 | K27: -49.546675 | L27: -0.52526453
A28: 2025 | B28: 7 | C28: =DATE('MODELO 5'!$A28,'MODELO 5'!$B28,1) -> 7/1/2025 | D28: 698 | E28: 12 | F28: 3.6381039 | I28: 3 | J28: 551.73964 | K28: 105.26036 | L28: 1.1159081
A29: 2025 | B29: 8 | C29: =DATE('MODELO 5'!$A29,'MODELO 5'!$B29,1) -> 8/1/2025 | D29: 645 | E29: 12 | F29: 3.7901712 | I29: 4 | J29: 557.15194 | K29: 67.848064 | L29: 0.71928504
A30: 2025 | B30: 9 | C30: =DATE('MODELO 5'!$A30,'MODELO 5'!$B30,1) -> 9/1/2025 | D30: 741 | E30: 12 | F30: 3.6670321 | I30: 5 | J30: 580.73614 | K30: 104.26386 | L30: 1.1053437
A31: 2025 | B31: 10 | C31: =DATE('MODELO 5'!$A31,'MODELO 5'!$B31,1) -> 10/1/2025 | D31: 626 | E31: 12 | F31: 3.6709379 | I31: 6 | J31: 595.07969 | K31: 62.920309 | L31: 0.66704389
A32: 2025 | B32: 11 | C32: =DATE('MODELO 5'!$A32,'MODELO 5'!$B32,1) -> 11/1/2025 | D32: 501 | E32: 12 | F32: 3.7034957 | I32: 7 | J32: 592.85166 | K32: 39.148336 | L32: 0.41502749
A33: 2025 | B33: 12 | C33: =DATE('MODELO 5'!$A33,'MODELO 5'!$B33,1) -> 12/1/2025 | D33: 411 | E33: 12 | F33: 3.833291 | I33: 8 | J33: 582.85764 | K33: -39.857637 | L33: -0.42254708
A34: 2026 | B34: 1 | C34: =DATE('MODELO 5'!$A34,'MODELO 5'!$B34,1) -> 1/1/2026 | D34: 386 | E34: 12 | F34: 3.5321787 | I34: 9 | J34: 563.68654 | K34: -61.68654 | L34: -0.6539642
A35: 2026 | B35: 2 | C35: =DATE('MODELO 5'!$A35,'MODELO 5'!$B35,1) -> 2/1/2026 | D35: 406 | E35: 12 | F35: 3.4428723 | I35: 10 | J35: 561.47256 | K35: -158.47256 | L35: -1.6800323
A36: 2026 | B36: 3 | C36: =DATE('MODELO 5'!$A36,'MODELO 5'!$B36,1) -> 3/1/2026 | D36: 589 | E36: 12 | F36: 3.65865 | I36: 11 | J36: 571.46604 | K36: -144.46604 | L36: -1.5315434
I37: 12 | J37: 571.21967 | K37: -4.2196652 | L37: -0.044734394
I38: 13 | J38: 573.58112 | K38: -10.581121 | L38: -0.11217479
I39: 14 | J39: 564.36709 | K39: 8.6329119 | L39: 0.091521024
I40: 15 | J40: 566.17901 | K40: 33.820988 | L40: 0.35855011
...
